[INFO] 2025-10-30 06:47:00 django.utils.autoreload 82033 139883829667648 Watching for file changes with StatReloader
[INFO] 2025-10-30 06:48:49 django.utils.autoreload 82272 139942895773504 Watching for file changes with StatReloader
[WARNING] 2025-10-30 06:57:44 django.request 91707 140040747693888 Unauthorized: /api/v1/job-orders/
[WARNING] 2025-10-30 06:57:44 django.request 91710 140040747693888 Unauthorized: /api/v1/tasks/
[WARNING] 2025-10-30 06:57:44 django.request 91707 140040747693888 Not Found: /auth/token/refresh/
[WARNING] 2025-10-30 06:57:44 django.request 91708 140040747693888 Unauthorized: /api/v1/users/
[WARNING] 2025-10-30 06:57:44 django.request 91709 140040747693888 Not Found: /auth/token/refresh/
[WARNING] 2025-10-30 06:57:52 django.request 91710 140040747693888 Unauthorized: /api/v1/tasks/
[ERROR] 2025-10-30 06:58:53 django.request 91709 140040747693888 Internal Server Error: /api/v1/metrics/job-order/1/
Traceback (most recent call last):
  File "/home/coderx64/hackathon/backend/venv/lib/python3.14/site-packages/django/db/backends/utils.py", line 105, in _execute
    return self.cursor.execute(sql, params)
           ~~~~~~~~~~~~~~~~~~~^^^^^^^^^^^^^
  File "/home/coderx64/hackathon/backend/venv/lib/python3.14/site-packages/django/db/backends/sqlite3/base.py", line 360, in execute
    return super().execute(query, params)
           ~~~~~~~~~~~~~~~^^^^^^^^^^^^^^^
sqlite3.OperationalError: no such table: users

The above exception was the direct cause of the following exception:

Traceback (most recent call last):
  File "/home/coderx64/hackathon/backend/venv/lib/python3.14/site-packages/django/core/handlers/exception.py", line 55, in inner
    response = get_response(request)
  File "/home/coderx64/hackathon/backend/venv/lib/python3.14/site-packages/django/core/handlers/base.py", line 197, in _get_response
    response = wrapped_callback(request, *callback_args, **callback_kwargs)
  File "/home/coderx64/hackathon/backend/venv/lib/python3.14/site-packages/django/views/decorators/csrf.py", line 65, in _view_wrapper
    return view_func(request, *args, **kwargs)
  File "/home/coderx64/hackathon/backend/venv/lib/python3.14/site-packages/django/views/generic/base.py", line 105, in view
    return self.dispatch(request, *args, **kwargs)
           ~~~~~~~~~~~~~^^^^^^^^^^^^^^^^^^^^^^^^^^
  File "/home/coderx64/hackathon/backend/venv/lib/python3.14/site-packages/rest_framework/views.py", line 515, in dispatch
    response = self.handle_exception(exc)
  File "/home/coderx64/hackathon/backend/venv/lib/python3.14/site-packages/rest_framework/views.py", line 475, in handle_exception
    self.raise_uncaught_exception(exc)
    ~~~~~~~~~~~~~~~~~~~~~~~~~~~~~^^^^^
  File "/home/coderx64/hackathon/backend/venv/lib/python3.14/site-packages/rest_framework/views.py", line 486, in raise_uncaught_exception
    raise exc
  File "/home/coderx64/hackathon/backend/venv/lib/python3.14/site-packages/rest_framework/views.py", line 503, in dispatch
    self.initial(request, *args, **kwargs)
    ~~~~~~~~~~~~^^^^^^^^^^^^^^^^^^^^^^^^^^
  File "/home/coderx64/hackathon/backend/venv/lib/python3.14/site-packages/rest_framework/views.py", line 420, in initial
    self.perform_authentication(request)
    ~~~~~~~~~~~~~~~~~~~~~~~~~~~^^^^^^^^^
  File "/home/coderx64/hackathon/backend/venv/lib/python3.14/site-packages/rest_framework/views.py", line 330, in perform_authentication
    request.user
  File "/home/coderx64/hackathon/backend/venv/lib/python3.14/site-packages/rest_framework/request.py", line 232, in user
    self._authenticate()
    ~~~~~~~~~~~~~~~~~~^^
  File "/home/coderx64/hackathon/backend/venv/lib/python3.14/site-packages/rest_framework/request.py", line 385, in _authenticate
    user_auth_tuple = authenticator.authenticate(self)
  File "/home/coderx64/hackathon/backend/venv/lib/python3.14/site-packages/rest_framework_simplejwt/authentication.py", line 51, in authenticate
    return self.get_user(validated_token), validated_token
           ~~~~~~~~~~~~~^^^^^^^^^^^^^^^^^
  File "/home/coderx64/hackathon/backend/venv/lib/python3.14/site-packages/rest_framework_simplejwt/authentication.py", line 132, in get_user
    user = self.user_model.objects.get(**{api_settings.USER_ID_FIELD: user_id})
  File "/home/coderx64/hackathon/backend/venv/lib/python3.14/site-packages/django/db/models/manager.py", line 87, in manager_method
    return getattr(self.get_queryset(), name)(*args, **kwargs)
           ~~~~~~~~~~~~~~~~~~~~~~~~~~~~~~~~~~^^^^^^^^^^^^^^^^^
  File "/home/coderx64/hackathon/backend/venv/lib/python3.14/site-packages/django/db/models/query.py", line 629, in get
    num = len(clone)
  File "/home/coderx64/hackathon/backend/venv/lib/python3.14/site-packages/django/db/models/query.py", line 366, in __len__
    self._fetch_all()
    ~~~~~~~~~~~~~~~^^
  File "/home/coderx64/hackathon/backend/venv/lib/python3.14/site-packages/django/db/models/query.py", line 1949, in _fetch_all
    self._result_cache = list(self._iterable_class(self))
                         ~~~~^^^^^^^^^^^^^^^^^^^^^^^^^^^^
  File "/home/coderx64/hackathon/backend/venv/lib/python3.14/site-packages/django/db/models/query.py", line 91, in __iter__
    results = compiler.execute_sql(
        chunked_fetch=self.chunked_fetch, chunk_size=self.chunk_size
    )
  File "/home/coderx64/hackathon/backend/venv/lib/python3.14/site-packages/django/db/models/sql/compiler.py", line 1623, in execute_sql
    cursor.execute(sql, params)
    ~~~~~~~~~~~~~~^^^^^^^^^^^^^
  File "/home/coderx64/hackathon/backend/venv/lib/python3.14/site-packages/django/db/backends/utils.py", line 79, in execute
    return self._execute_with_wrappers(
           ~~~~~~~~~~~~~~~~~~~~~~~~~~~^
        sql, params, many=False, executor=self._execute
        ^^^^^^^^^^^^^^^^^^^^^^^^^^^^^^^^^^^^^^^^^^^^^^^
    )
    ^
  File "/home/coderx64/hackathon/backend/venv/lib/python3.14/site-packages/django/db/backends/utils.py", line 92, in _execute_with_wrappers
    return executor(sql, params, many, context)
  File "/home/coderx64/hackathon/backend/venv/lib/python3.14/site-packages/django/db/backends/utils.py", line 100, in _execute
    with self.db.wrap_database_errors:
         ^^^^^^^^^^^^^^^^^^^^^^^^^^^^
  File "/home/coderx64/hackathon/backend/venv/lib/python3.14/site-packages/django/db/utils.py", line 91, in __exit__
    raise dj_exc_value.with_traceback(traceback) from exc_value
  File "/home/coderx64/hackathon/backend/venv/lib/python3.14/site-packages/django/db/backends/utils.py", line 105, in _execute
    return self.cursor.execute(sql, params)
           ~~~~~~~~~~~~~~~~~~~^^^^^^^^^^^^^
  File "/home/coderx64/hackathon/backend/venv/lib/python3.14/site-packages/django/db/backends/sqlite3/base.py", line 360, in execute
    return super().execute(query, params)
           ~~~~~~~~~~~~~~~^^^^^^^^^^^^^^^
django.db.utils.OperationalError: no such table: users
[ERROR] 2025-10-30 06:58:53 django.request 91710 140040747693888 Internal Server Error: /api/v1/job-orders/1/
Traceback (most recent call last):
  File "/home/coderx64/hackathon/backend/venv/lib/python3.14/site-packages/django/db/backends/utils.py", line 105, in _execute
    return self.cursor.execute(sql, params)
           ~~~~~~~~~~~~~~~~~~~^^^^^^^^^^^^^
  File "/home/coderx64/hackathon/backend/venv/lib/python3.14/site-packages/django/db/backends/sqlite3/base.py", line 360, in execute
    return super().execute(query, params)
           ~~~~~~~~~~~~~~~^^^^^^^^^^^^^^^
sqlite3.OperationalError: no such table: users

The above exception was the direct cause of the following exception:

Traceback (most recent call last):
  File "/home/coderx64/hackathon/backend/venv/lib/python3.14/site-packages/django/core/handlers/exception.py", line 55, in inner
    response = get_response(request)
  File "/home/coderx64/hackathon/backend/venv/lib/python3.14/site-packages/django/core/handlers/base.py", line 197, in _get_response
    response = wrapped_callback(request, *callback_args, **callback_kwargs)
  File "/home/coderx64/hackathon/backend/venv/lib/python3.14/site-packages/django/views/decorators/csrf.py", line 65, in _view_wrapper
    return view_func(request, *args, **kwargs)
  File "/home/coderx64/hackathon/backend/venv/lib/python3.14/site-packages/rest_framework/viewsets.py", line 125, in view
    return self.dispatch(request, *args, **kwargs)
           ~~~~~~~~~~~~~^^^^^^^^^^^^^^^^^^^^^^^^^^
  File "/home/coderx64/hackathon/backend/venv/lib/python3.14/site-packages/rest_framework/views.py", line 515, in dispatch
    response = self.handle_exception(exc)
  File "/home/coderx64/hackathon/backend/venv/lib/python3.14/site-packages/rest_framework/views.py", line 475, in handle_exception
    self.raise_uncaught_exception(exc)
    ~~~~~~~~~~~~~~~~~~~~~~~~~~~~~^^^^^
  File "/home/coderx64/hackathon/backend/venv/lib/python3.14/site-packages/rest_framework/views.py", line 486, in raise_uncaught_exception
    raise exc
  File "/home/coderx64/hackathon/backend/venv/lib/python3.14/site-packages/rest_framework/views.py", line 503, in dispatch
    self.initial(request, *args, **kwargs)
    ~~~~~~~~~~~~^^^^^^^^^^^^^^^^^^^^^^^^^^
  File "/home/coderx64/hackathon/backend/venv/lib/python3.14/site-packages/rest_framework/views.py", line 420, in initial
    self.perform_authentication(request)
    ~~~~~~~~~~~~~~~~~~~~~~~~~~~^^^^^^^^^
  File "/home/coderx64/hackathon/backend/venv/lib/python3.14/site-packages/rest_framework/views.py", line 330, in perform_authentication
    request.user
  File "/home/coderx64/hackathon/backend/venv/lib/python3.14/site-packages/rest_framework/request.py", line 232, in user
    self._authenticate()
    ~~~~~~~~~~~~~~~~~~^^
  File "/home/coderx64/hackathon/backend/venv/lib/python3.14/site-packages/rest_framework/request.py", line 385, in _authenticate
    user_auth_tuple = authenticator.authenticate(self)
  File "/home/coderx64/hackathon/backend/venv/lib/python3.14/site-packages/rest_framework_simplejwt/authentication.py", line 51, in authenticate
    return self.get_user(validated_token), validated_token
           ~~~~~~~~~~~~~^^^^^^^^^^^^^^^^^
  File "/home/coderx64/hackathon/backend/venv/lib/python3.14/site-packages/rest_framework_simplejwt/authentication.py", line 132, in get_user
    user = self.user_model.objects.get(**{api_settings.USER_ID_FIELD: user_id})
  File "/home/coderx64/hackathon/backend/venv/lib/python3.14/site-packages/django/db/models/manager.py", line 87, in manager_method
    return getattr(self.get_queryset(), name)(*args, **kwargs)
           ~~~~~~~~~~~~~~~~~~~~~~~~~~~~~~~~~~^^^^^^^^^^^^^^^^^
  File "/home/coderx64/hackathon/backend/venv/lib/python3.14/site-packages/django/db/models/query.py", line 629, in get
    num = len(clone)
  File "/home/coderx64/hackathon/backend/venv/lib/python3.14/site-packages/django/db/models/query.py", line 366, in __len__
    self._fetch_all()
    ~~~~~~~~~~~~~~~^^
  File "/home/coderx64/hackathon/backend/venv/lib/python3.14/site-packages/django/db/models/query.py", line 1949, in _fetch_all
    self._result_cache = list(self._iterable_class(self))
                         ~~~~^^^^^^^^^^^^^^^^^^^^^^^^^^^^
  File "/home/coderx64/hackathon/backend/venv/lib/python3.14/site-packages/django/db/models/query.py", line 91, in __iter__
    results = compiler.execute_sql(
        chunked_fetch=self.chunked_fetch, chunk_size=self.chunk_size
    )
  File "/home/coderx64/hackathon/backend/venv/lib/python3.14/site-packages/django/db/models/sql/compiler.py", line 1623, in execute_sql
    cursor.execute(sql, params)
    ~~~~~~~~~~~~~~^^^^^^^^^^^^^
  File "/home/coderx64/hackathon/backend/venv/lib/python3.14/site-packages/django/db/backends/utils.py", line 79, in execute
    return self._execute_with_wrappers(
           ~~~~~~~~~~~~~~~~~~~~~~~~~~~^
        sql, params, many=False, executor=self._execute
        ^^^^^^^^^^^^^^^^^^^^^^^^^^^^^^^^^^^^^^^^^^^^^^^
    )
    ^
  File "/home/coderx64/hackathon/backend/venv/lib/python3.14/site-packages/django/db/backends/utils.py", line 92, in _execute_with_wrappers
    return executor(sql, params, many, context)
  File "/home/coderx64/hackathon/backend/venv/lib/python3.14/site-packages/django/db/backends/utils.py", line 100, in _execute
    with self.db.wrap_database_errors:
         ^^^^^^^^^^^^^^^^^^^^^^^^^^^^
  File "/home/coderx64/hackathon/backend/venv/lib/python3.14/site-packages/django/db/utils.py", line 91, in __exit__
    raise dj_exc_value.with_traceback(traceback) from exc_value
  File "/home/coderx64/hackathon/backend/venv/lib/python3.14/site-packages/django/db/backends/utils.py", line 105, in _execute
    return self.cursor.execute(sql, params)
           ~~~~~~~~~~~~~~~~~~~^^^^^^^^^^^^^
  File "/home/coderx64/hackathon/backend/venv/lib/python3.14/site-packages/django/db/backends/sqlite3/base.py", line 360, in execute
    return super().execute(query, params)
           ~~~~~~~~~~~~~~~^^^^^^^^^^^^^^^
django.db.utils.OperationalError: no such table: users
[ERROR] 2025-10-30 06:58:57 django.request 91709 140040747693888 Internal Server Error: /api/v1/job-orders/
Traceback (most recent call last):
  File "/home/coderx64/hackathon/backend/venv/lib/python3.14/site-packages/django/db/backends/utils.py", line 105, in _execute
    return self.cursor.execute(sql, params)
           ~~~~~~~~~~~~~~~~~~~^^^^^^^^^^^^^
  File "/home/coderx64/hackathon/backend/venv/lib/python3.14/site-packages/django/db/backends/sqlite3/base.py", line 360, in execute
    return super().execute(query, params)
           ~~~~~~~~~~~~~~~^^^^^^^^^^^^^^^
sqlite3.OperationalError: no such table: users

The above exception was the direct cause of the following exception:

Traceback (most recent call last):
  File "/home/coderx64/hackathon/backend/venv/lib/python3.14/site-packages/django/core/handlers/exception.py", line 55, in inner
    response = get_response(request)
  File "/home/coderx64/hackathon/backend/venv/lib/python3.14/site-packages/django/core/handlers/base.py", line 197, in _get_response
    response = wrapped_callback(request, *callback_args, **callback_kwargs)
  File "/home/coderx64/hackathon/backend/venv/lib/python3.14/site-packages/django/views/decorators/csrf.py", line 65, in _view_wrapper
    return view_func(request, *args, **kwargs)
  File "/home/coderx64/hackathon/backend/venv/lib/python3.14/site-packages/rest_framework/viewsets.py", line 125, in view
    return self.dispatch(request, *args, **kwargs)
           ~~~~~~~~~~~~~^^^^^^^^^^^^^^^^^^^^^^^^^^
  File "/home/coderx64/hackathon/backend/venv/lib/python3.14/site-packages/rest_framework/views.py", line 515, in dispatch
    response = self.handle_exception(exc)
  File "/home/coderx64/hackathon/backend/venv/lib/python3.14/site-packages/rest_framework/views.py", line 475, in handle_exception
    self.raise_uncaught_exception(exc)
    ~~~~~~~~~~~~~~~~~~~~~~~~~~~~~^^^^^
  File "/home/coderx64/hackathon/backend/venv/lib/python3.14/site-packages/rest_framework/views.py", line 486, in raise_uncaught_exception
    raise exc
  File "/home/coderx64/hackathon/backend/venv/lib/python3.14/site-packages/rest_framework/views.py", line 503, in dispatch
    self.initial(request, *args, **kwargs)
    ~~~~~~~~~~~~^^^^^^^^^^^^^^^^^^^^^^^^^^
  File "/home/coderx64/hackathon/backend/venv/lib/python3.14/site-packages/rest_framework/views.py", line 420, in initial
    self.perform_authentication(request)
    ~~~~~~~~~~~~~~~~~~~~~~~~~~~^^^^^^^^^
  File "/home/coderx64/hackathon/backend/venv/lib/python3.14/site-packages/rest_framework/views.py", line 330, in perform_authentication
    request.user
  File "/home/coderx64/hackathon/backend/venv/lib/python3.14/site-packages/rest_framework/request.py", line 232, in user
    self._authenticate()
    ~~~~~~~~~~~~~~~~~~^^
  File "/home/coderx64/hackathon/backend/venv/lib/python3.14/site-packages/rest_framework/request.py", line 385, in _authenticate
    user_auth_tuple = authenticator.authenticate(self)
  File "/home/coderx64/hackathon/backend/venv/lib/python3.14/site-packages/rest_framework_simplejwt/authentication.py", line 51, in authenticate
    return self.get_user(validated_token), validated_token
           ~~~~~~~~~~~~~^^^^^^^^^^^^^^^^^
  File "/home/coderx64/hackathon/backend/venv/lib/python3.14/site-packages/rest_framework_simplejwt/authentication.py", line 132, in get_user
    user = self.user_model.objects.get(**{api_settings.USER_ID_FIELD: user_id})
  File "/home/coderx64/hackathon/backend/venv/lib/python3.14/site-packages/django/db/models/manager.py", line 87, in manager_method
    return getattr(self.get_queryset(), name)(*args, **kwargs)
           ~~~~~~~~~~~~~~~~~~~~~~~~~~~~~~~~~~^^^^^^^^^^^^^^^^^
  File "/home/coderx64/hackathon/backend/venv/lib/python3.14/site-packages/django/db/models/query.py", line 629, in get
    num = len(clone)
  File "/home/coderx64/hackathon/backend/venv/lib/python3.14/site-packages/django/db/models/query.py", line 366, in __len__
    self._fetch_all()
    ~~~~~~~~~~~~~~~^^
  File "/home/coderx64/hackathon/backend/venv/lib/python3.14/site-packages/django/db/models/query.py", line 1949, in _fetch_all
    self._result_cache = list(self._iterable_class(self))
                         ~~~~^^^^^^^^^^^^^^^^^^^^^^^^^^^^
  File "/home/coderx64/hackathon/backend/venv/lib/python3.14/site-packages/django/db/models/query.py", line 91, in __iter__
    results = compiler.execute_sql(
        chunked_fetch=self.chunked_fetch, chunk_size=self.chunk_size
    )
  File "/home/coderx64/hackathon/backend/venv/lib/python3.14/site-packages/django/db/models/sql/compiler.py", line 1623, in execute_sql
    cursor.execute(sql, params)
    ~~~~~~~~~~~~~~^^^^^^^^^^^^^
  File "/home/coderx64/hackathon/backend/venv/lib/python3.14/site-packages/django/db/backends/utils.py", line 79, in execute
    return self._execute_with_wrappers(
           ~~~~~~~~~~~~~~~~~~~~~~~~~~~^
        sql, params, many=False, executor=self._execute
        ^^^^^^^^^^^^^^^^^^^^^^^^^^^^^^^^^^^^^^^^^^^^^^^
    )
    ^
  File "/home/coderx64/hackathon/backend/venv/lib/python3.14/site-packages/django/db/backends/utils.py", line 92, in _execute_with_wrappers
    return executor(sql, params, many, context)
  File "/home/coderx64/hackathon/backend/venv/lib/python3.14/site-packages/django/db/backends/utils.py", line 100, in _execute
    with self.db.wrap_database_errors:
         ^^^^^^^^^^^^^^^^^^^^^^^^^^^^
  File "/home/coderx64/hackathon/backend/venv/lib/python3.14/site-packages/django/db/utils.py", line 91, in __exit__
    raise dj_exc_value.with_traceback(traceback) from exc_value
  File "/home/coderx64/hackathon/backend/venv/lib/python3.14/site-packages/django/db/backends/utils.py", line 105, in _execute
    return self.cursor.execute(sql, params)
           ~~~~~~~~~~~~~~~~~~~^^^^^^^^^^^^^
  File "/home/coderx64/hackathon/backend/venv/lib/python3.14/site-packages/django/db/backends/sqlite3/base.py", line 360, in execute
    return super().execute(query, params)
           ~~~~~~~~~~~~~~~^^^^^^^^^^^^^^^
django.db.utils.OperationalError: no such table: users
[ERROR] 2025-10-30 06:58:57 django.request 91707 140040747693888 Internal Server Error: /api/v1/tasks/
Traceback (most recent call last):
  File "/home/coderx64/hackathon/backend/venv/lib/python3.14/site-packages/django/db/backends/utils.py", line 105, in _execute
    return self.cursor.execute(sql, params)
           ~~~~~~~~~~~~~~~~~~~^^^^^^^^^^^^^
  File "/home/coderx64/hackathon/backend/venv/lib/python3.14/site-packages/django/db/backends/sqlite3/base.py", line 360, in execute
    return super().execute(query, params)
           ~~~~~~~~~~~~~~~^^^^^^^^^^^^^^^
sqlite3.OperationalError: no such table: users

The above exception was the direct cause of the following exception:

Traceback (most recent call last):
  File "/home/coderx64/hackathon/backend/venv/lib/python3.14/site-packages/django/core/handlers/exception.py", line 55, in inner
    response = get_response(request)
  File "/home/coderx64/hackathon/backend/venv/lib/python3.14/site-packages/django/core/handlers/base.py", line 197, in _get_response
    response = wrapped_callback(request, *callback_args, **callback_kwargs)
  File "/home/coderx64/hackathon/backend/venv/lib/python3.14/site-packages/django/views/decorators/csrf.py", line 65, in _view_wrapper
    return view_func(request, *args, **kwargs)
  File "/home/coderx64/hackathon/backend/venv/lib/python3.14/site-packages/rest_framework/viewsets.py", line 125, in view
    return self.dispatch(request, *args, **kwargs)
           ~~~~~~~~~~~~~^^^^^^^^^^^^^^^^^^^^^^^^^^
  File "/home/coderx64/hackathon/backend/venv/lib/python3.14/site-packages/rest_framework/views.py", line 515, in dispatch
    response = self.handle_exception(exc)
  File "/home/coderx64/hackathon/backend/venv/lib/python3.14/site-packages/rest_framework/views.py", line 475, in handle_exception
    self.raise_uncaught_exception(exc)
    ~~~~~~~~~~~~~~~~~~~~~~~~~~~~~^^^^^
  File "/home/coderx64/hackathon/backend/venv/lib/python3.14/site-packages/rest_framework/views.py", line 486, in raise_uncaught_exception
    raise exc
  File "/home/coderx64/hackathon/backend/venv/lib/python3.14/site-packages/rest_framework/views.py", line 503, in dispatch
    self.initial(request, *args, **kwargs)
    ~~~~~~~~~~~~^^^^^^^^^^^^^^^^^^^^^^^^^^
  File "/home/coderx64/hackathon/backend/venv/lib/python3.14/site-packages/rest_framework/views.py", line 420, in initial
    self.perform_authentication(request)
    ~~~~~~~~~~~~~~~~~~~~~~~~~~~^^^^^^^^^
  File "/home/coderx64/hackathon/backend/venv/lib/python3.14/site-packages/rest_framework/views.py", line 330, in perform_authentication
    request.user
  File "/home/coderx64/hackathon/backend/venv/lib/python3.14/site-packages/rest_framework/request.py", line 232, in user
    self._authenticate()
    ~~~~~~~~~~~~~~~~~~^^
  File "/home/coderx64/hackathon/backend/venv/lib/python3.14/site-packages/rest_framework/request.py", line 385, in _authenticate
    user_auth_tuple = authenticator.authenticate(self)
  File "/home/coderx64/hackathon/backend/venv/lib/python3.14/site-packages/rest_framework_simplejwt/authentication.py", line 51, in authenticate
    return self.get_user(validated_token), validated_token
           ~~~~~~~~~~~~~^^^^^^^^^^^^^^^^^
  File "/home/coderx64/hackathon/backend/venv/lib/python3.14/site-packages/rest_framework_simplejwt/authentication.py", line 132, in get_user
    user = self.user_model.objects.get(**{api_settings.USER_ID_FIELD: user_id})
  File "/home/coderx64/hackathon/backend/venv/lib/python3.14/site-packages/django/db/models/manager.py", line 87, in manager_method
    return getattr(self.get_queryset(), name)(*args, **kwargs)
           ~~~~~~~~~~~~~~~~~~~~~~~~~~~~~~~~~~^^^^^^^^^^^^^^^^^
  File "/home/coderx64/hackathon/backend/venv/lib/python3.14/site-packages/django/db/models/query.py", line 629, in get
    num = len(clone)
  File "/home/coderx64/hackathon/backend/venv/lib/python3.14/site-packages/django/db/models/query.py", line 366, in __len__
    self._fetch_all()
    ~~~~~~~~~~~~~~~^^
  File "/home/coderx64/hackathon/backend/venv/lib/python3.14/site-packages/django/db/models/query.py", line 1949, in _fetch_all
    self._result_cache = list(self._iterable_class(self))
                         ~~~~^^^^^^^^^^^^^^^^^^^^^^^^^^^^
  File "/home/coderx64/hackathon/backend/venv/lib/python3.14/site-packages/django/db/models/query.py", line 91, in __iter__
    results = compiler.execute_sql(
        chunked_fetch=self.chunked_fetch, chunk_size=self.chunk_size
    )
  File "/home/coderx64/hackathon/backend/venv/lib/python3.14/site-packages/django/db/models/sql/compiler.py", line 1623, in execute_sql
    cursor.execute(sql, params)
    ~~~~~~~~~~~~~~^^^^^^^^^^^^^
  File "/home/coderx64/hackathon/backend/venv/lib/python3.14/site-packages/django/db/backends/utils.py", line 79, in execute
    return self._execute_with_wrappers(
           ~~~~~~~~~~~~~~~~~~~~~~~~~~~^
        sql, params, many=False, executor=self._execute
        ^^^^^^^^^^^^^^^^^^^^^^^^^^^^^^^^^^^^^^^^^^^^^^^
    )
    ^
  File "/home/coderx64/hackathon/backend/venv/lib/python3.14/site-packages/django/db/backends/utils.py", line 92, in _execute_with_wrappers
    return executor(sql, params, many, context)
  File "/home/coderx64/hackathon/backend/venv/lib/python3.14/site-packages/django/db/backends/utils.py", line 100, in _execute
    with self.db.wrap_database_errors:
         ^^^^^^^^^^^^^^^^^^^^^^^^^^^^
  File "/home/coderx64/hackathon/backend/venv/lib/python3.14/site-packages/django/db/utils.py", line 91, in __exit__
    raise dj_exc_value.with_traceback(traceback) from exc_value
  File "/home/coderx64/hackathon/backend/venv/lib/python3.14/site-packages/django/db/backends/utils.py", line 105, in _execute
    return self.cursor.execute(sql, params)
           ~~~~~~~~~~~~~~~~~~~^^^^^^^^^^^^^
  File "/home/coderx64/hackathon/backend/venv/lib/python3.14/site-packages/django/db/backends/sqlite3/base.py", line 360, in execute
    return super().execute(query, params)
           ~~~~~~~~~~~~~~~^^^^^^^^^^^^^^^
django.db.utils.OperationalError: no such table: users
[ERROR] 2025-10-30 06:59:41 django.request 92121 140199602079552 Internal Server Error: /api/v1/tasks/
Traceback (most recent call last):
  File "/home/coderx64/hackathon/backend/venv/lib/python3.14/site-packages/django/db/backends/utils.py", line 105, in _execute
    return self.cursor.execute(sql, params)
           ~~~~~~~~~~~~~~~~~~~^^^^^^^^^^^^^
  File "/home/coderx64/hackathon/backend/venv/lib/python3.14/site-packages/django/db/backends/sqlite3/base.py", line 360, in execute
    return super().execute(query, params)
           ~~~~~~~~~~~~~~~^^^^^^^^^^^^^^^
sqlite3.OperationalError: no such table: users

The above exception was the direct cause of the following exception:

Traceback (most recent call last):
  File "/home/coderx64/hackathon/backend/venv/lib/python3.14/site-packages/django/core/handlers/exception.py", line 55, in inner
    response = get_response(request)
  File "/home/coderx64/hackathon/backend/venv/lib/python3.14/site-packages/django/core/handlers/base.py", line 197, in _get_response
    response = wrapped_callback(request, *callback_args, **callback_kwargs)
  File "/home/coderx64/hackathon/backend/venv/lib/python3.14/site-packages/django/views/decorators/csrf.py", line 65, in _view_wrapper
    return view_func(request, *args, **kwargs)
  File "/home/coderx64/hackathon/backend/venv/lib/python3.14/site-packages/rest_framework/viewsets.py", line 125, in view
    return self.dispatch(request, *args, **kwargs)
           ~~~~~~~~~~~~~^^^^^^^^^^^^^^^^^^^^^^^^^^
  File "/home/coderx64/hackathon/backend/venv/lib/python3.14/site-packages/rest_framework/views.py", line 515, in dispatch
    response = self.handle_exception(exc)
  File "/home/coderx64/hackathon/backend/venv/lib/python3.14/site-packages/rest_framework/views.py", line 475, in handle_exception
    self.raise_uncaught_exception(exc)
    ~~~~~~~~~~~~~~~~~~~~~~~~~~~~~^^^^^
  File "/home/coderx64/hackathon/backend/venv/lib/python3.14/site-packages/rest_framework/views.py", line 486, in raise_uncaught_exception
    raise exc
  File "/home/coderx64/hackathon/backend/venv/lib/python3.14/site-packages/rest_framework/views.py", line 503, in dispatch
    self.initial(request, *args, **kwargs)
    ~~~~~~~~~~~~^^^^^^^^^^^^^^^^^^^^^^^^^^
  File "/home/coderx64/hackathon/backend/venv/lib/python3.14/site-packages/rest_framework/views.py", line 420, in initial
    self.perform_authentication(request)
    ~~~~~~~~~~~~~~~~~~~~~~~~~~~^^^^^^^^^
  File "/home/coderx64/hackathon/backend/venv/lib/python3.14/site-packages/rest_framework/views.py", line 330, in perform_authentication
    request.user
  File "/home/coderx64/hackathon/backend/venv/lib/python3.14/site-packages/rest_framework/request.py", line 232, in user
    self._authenticate()
    ~~~~~~~~~~~~~~~~~~^^
  File "/home/coderx64/hackathon/backend/venv/lib/python3.14/site-packages/rest_framework/request.py", line 385, in _authenticate
    user_auth_tuple = authenticator.authenticate(self)
  File "/home/coderx64/hackathon/backend/venv/lib/python3.14/site-packages/rest_framework_simplejwt/authentication.py", line 51, in authenticate
    return self.get_user(validated_token), validated_token
           ~~~~~~~~~~~~~^^^^^^^^^^^^^^^^^
  File "/home/coderx64/hackathon/backend/venv/lib/python3.14/site-packages/rest_framework_simplejwt/authentication.py", line 132, in get_user
    user = self.user_model.objects.get(**{api_settings.USER_ID_FIELD: user_id})
  File "/home/coderx64/hackathon/backend/venv/lib/python3.14/site-packages/django/db/models/manager.py", line 87, in manager_method
    return getattr(self.get_queryset(), name)(*args, **kwargs)
           ~~~~~~~~~~~~~~~~~~~~~~~~~~~~~~~~~~^^^^^^^^^^^^^^^^^
  File "/home/coderx64/hackathon/backend/venv/lib/python3.14/site-packages/django/db/models/query.py", line 629, in get
    num = len(clone)
  File "/home/coderx64/hackathon/backend/venv/lib/python3.14/site-packages/django/db/models/query.py", line 366, in __len__
    self._fetch_all()
    ~~~~~~~~~~~~~~~^^
  File "/home/coderx64/hackathon/backend/venv/lib/python3.14/site-packages/django/db/models/query.py", line 1949, in _fetch_all
    self._result_cache = list(self._iterable_class(self))
                         ~~~~^^^^^^^^^^^^^^^^^^^^^^^^^^^^
  File "/home/coderx64/hackathon/backend/venv/lib/python3.14/site-packages/django/db/models/query.py", line 91, in __iter__
    results = compiler.execute_sql(
        chunked_fetch=self.chunked_fetch, chunk_size=self.chunk_size
    )
  File "/home/coderx64/hackathon/backend/venv/lib/python3.14/site-packages/django/db/models/sql/compiler.py", line 1623, in execute_sql
    cursor.execute(sql, params)
    ~~~~~~~~~~~~~~^^^^^^^^^^^^^
  File "/home/coderx64/hackathon/backend/venv/lib/python3.14/site-packages/django/db/backends/utils.py", line 79, in execute
    return self._execute_with_wrappers(
           ~~~~~~~~~~~~~~~~~~~~~~~~~~~^
        sql, params, many=False, executor=self._execute
        ^^^^^^^^^^^^^^^^^^^^^^^^^^^^^^^^^^^^^^^^^^^^^^^
    )
    ^
  File "/home/coderx64/hackathon/backend/venv/lib/python3.14/site-packages/django/db/backends/utils.py", line 92, in _execute_with_wrappers
    return executor(sql, params, many, context)
  File "/home/coderx64/hackathon/backend/venv/lib/python3.14/site-packages/django/db/backends/utils.py", line 100, in _execute
    with self.db.wrap_database_errors:
         ^^^^^^^^^^^^^^^^^^^^^^^^^^^^
  File "/home/coderx64/hackathon/backend/venv/lib/python3.14/site-packages/django/db/utils.py", line 91, in __exit__
    raise dj_exc_value.with_traceback(traceback) from exc_value
  File "/home/coderx64/hackathon/backend/venv/lib/python3.14/site-packages/django/db/backends/utils.py", line 105, in _execute
    return self.cursor.execute(sql, params)
           ~~~~~~~~~~~~~~~~~~~^^^^^^^^^^^^^
  File "/home/coderx64/hackathon/backend/venv/lib/python3.14/site-packages/django/db/backends/sqlite3/base.py", line 360, in execute
    return super().execute(query, params)
           ~~~~~~~~~~~~~~~^^^^^^^^^^^^^^^
django.db.utils.OperationalError: no such table: users
[ERROR] 2025-10-30 06:59:41 django.request 92119 140199602079552 Internal Server Error: /api/v1/job-orders/
Traceback (most recent call last):
  File "/home/coderx64/hackathon/backend/venv/lib/python3.14/site-packages/django/db/backends/utils.py", line 105, in _execute
    return self.cursor.execute(sql, params)
           ~~~~~~~~~~~~~~~~~~~^^^^^^^^^^^^^
  File "/home/coderx64/hackathon/backend/venv/lib/python3.14/site-packages/django/db/backends/sqlite3/base.py", line 360, in execute
    return super().execute(query, params)
           ~~~~~~~~~~~~~~~^^^^^^^^^^^^^^^
sqlite3.OperationalError: no such table: users

The above exception was the direct cause of the following exception:

Traceback (most recent call last):
  File "/home/coderx64/hackathon/backend/venv/lib/python3.14/site-packages/django/core/handlers/exception.py", line 55, in inner
    response = get_response(request)
  File "/home/coderx64/hackathon/backend/venv/lib/python3.14/site-packages/django/core/handlers/base.py", line 197, in _get_response
    response = wrapped_callback(request, *callback_args, **callback_kwargs)
  File "/home/coderx64/hackathon/backend/venv/lib/python3.14/site-packages/django/views/decorators/csrf.py", line 65, in _view_wrapper
    return view_func(request, *args, **kwargs)
  File "/home/coderx64/hackathon/backend/venv/lib/python3.14/site-packages/rest_framework/viewsets.py", line 125, in view
    return self.dispatch(request, *args, **kwargs)
           ~~~~~~~~~~~~~^^^^^^^^^^^^^^^^^^^^^^^^^^
  File "/home/coderx64/hackathon/backend/venv/lib/python3.14/site-packages/rest_framework/views.py", line 515, in dispatch
    response = self.handle_exception(exc)
  File "/home/coderx64/hackathon/backend/venv/lib/python3.14/site-packages/rest_framework/views.py", line 475, in handle_exception
    self.raise_uncaught_exception(exc)
    ~~~~~~~~~~~~~~~~~~~~~~~~~~~~~^^^^^
  File "/home/coderx64/hackathon/backend/venv/lib/python3.14/site-packages/rest_framework/views.py", line 486, in raise_uncaught_exception
    raise exc
  File "/home/coderx64/hackathon/backend/venv/lib/python3.14/site-packages/rest_framework/views.py", line 503, in dispatch
    self.initial(request, *args, **kwargs)
    ~~~~~~~~~~~~^^^^^^^^^^^^^^^^^^^^^^^^^^
  File "/home/coderx64/hackathon/backend/venv/lib/python3.14/site-packages/rest_framework/views.py", line 420, in initial
    self.perform_authentication(request)
    ~~~~~~~~~~~~~~~~~~~~~~~~~~~^^^^^^^^^
  File "/home/coderx64/hackathon/backend/venv/lib/python3.14/site-packages/rest_framework/views.py", line 330, in perform_authentication
    request.user
  File "/home/coderx64/hackathon/backend/venv/lib/python3.14/site-packages/rest_framework/request.py", line 232, in user
    self._authenticate()
    ~~~~~~~~~~~~~~~~~~^^
  File "/home/coderx64/hackathon/backend/venv/lib/python3.14/site-packages/rest_framework/request.py", line 385, in _authenticate
    user_auth_tuple = authenticator.authenticate(self)
  File "/home/coderx64/hackathon/backend/venv/lib/python3.14/site-packages/rest_framework_simplejwt/authentication.py", line 51, in authenticate
    return self.get_user(validated_token), validated_token
           ~~~~~~~~~~~~~^^^^^^^^^^^^^^^^^
  File "/home/coderx64/hackathon/backend/venv/lib/python3.14/site-packages/rest_framework_simplejwt/authentication.py", line 132, in get_user
    user = self.user_model.objects.get(**{api_settings.USER_ID_FIELD: user_id})
  File "/home/coderx64/hackathon/backend/venv/lib/python3.14/site-packages/django/db/models/manager.py", line 87, in manager_method
    return getattr(self.get_queryset(), name)(*args, **kwargs)
           ~~~~~~~~~~~~~~~~~~~~~~~~~~~~~~~~~~^^^^^^^^^^^^^^^^^
  File "/home/coderx64/hackathon/backend/venv/lib/python3.14/site-packages/django/db/models/query.py", line 629, in get
    num = len(clone)
  File "/home/coderx64/hackathon/backend/venv/lib/python3.14/site-packages/django/db/models/query.py", line 366, in __len__
    self._fetch_all()
    ~~~~~~~~~~~~~~~^^
  File "/home/coderx64/hackathon/backend/venv/lib/python3.14/site-packages/django/db/models/query.py", line 1949, in _fetch_all
    self._result_cache = list(self._iterable_class(self))
                         ~~~~^^^^^^^^^^^^^^^^^^^^^^^^^^^^
  File "/home/coderx64/hackathon/backend/venv/lib/python3.14/site-packages/django/db/models/query.py", line 91, in __iter__
    results = compiler.execute_sql(
        chunked_fetch=self.chunked_fetch, chunk_size=self.chunk_size
    )
  File "/home/coderx64/hackathon/backend/venv/lib/python3.14/site-packages/django/db/models/sql/compiler.py", line 1623, in execute_sql
    cursor.execute(sql, params)
    ~~~~~~~~~~~~~~^^^^^^^^^^^^^
  File "/home/coderx64/hackathon/backend/venv/lib/python3.14/site-packages/django/db/backends/utils.py", line 79, in execute
    return self._execute_with_wrappers(
           ~~~~~~~~~~~~~~~~~~~~~~~~~~~^
        sql, params, many=False, executor=self._execute
        ^^^^^^^^^^^^^^^^^^^^^^^^^^^^^^^^^^^^^^^^^^^^^^^
    )
    ^
  File "/home/coderx64/hackathon/backend/venv/lib/python3.14/site-packages/django/db/backends/utils.py", line 92, in _execute_with_wrappers
    return executor(sql, params, many, context)
  File "/home/coderx64/hackathon/backend/venv/lib/python3.14/site-packages/django/db/backends/utils.py", line 100, in _execute
    with self.db.wrap_database_errors:
         ^^^^^^^^^^^^^^^^^^^^^^^^^^^^
  File "/home/coderx64/hackathon/backend/venv/lib/python3.14/site-packages/django/db/utils.py", line 91, in __exit__
    raise dj_exc_value.with_traceback(traceback) from exc_value
  File "/home/coderx64/hackathon/backend/venv/lib/python3.14/site-packages/django/db/backends/utils.py", line 105, in _execute
    return self.cursor.execute(sql, params)
           ~~~~~~~~~~~~~~~~~~~^^^^^^^^^^^^^
  File "/home/coderx64/hackathon/backend/venv/lib/python3.14/site-packages/django/db/backends/sqlite3/base.py", line 360, in execute
    return super().execute(query, params)
           ~~~~~~~~~~~~~~~^^^^^^^^^^^^^^^
django.db.utils.OperationalError: no such table: users
[ERROR] 2025-10-30 06:59:43 django.request 92121 140199602079552 Internal Server Error: /api/v1/tasks/
Traceback (most recent call last):
  File "/home/coderx64/hackathon/backend/venv/lib/python3.14/site-packages/django/db/backends/utils.py", line 105, in _execute
    return self.cursor.execute(sql, params)
           ~~~~~~~~~~~~~~~~~~~^^^^^^^^^^^^^
  File "/home/coderx64/hackathon/backend/venv/lib/python3.14/site-packages/django/db/backends/sqlite3/base.py", line 360, in execute
    return super().execute(query, params)
           ~~~~~~~~~~~~~~~^^^^^^^^^^^^^^^
sqlite3.OperationalError: no such table: users

The above exception was the direct cause of the following exception:

Traceback (most recent call last):
  File "/home/coderx64/hackathon/backend/venv/lib/python3.14/site-packages/django/core/handlers/exception.py", line 55, in inner
    response = get_response(request)
  File "/home/coderx64/hackathon/backend/venv/lib/python3.14/site-packages/django/core/handlers/base.py", line 197, in _get_response
    response = wrapped_callback(request, *callback_args, **callback_kwargs)
  File "/home/coderx64/hackathon/backend/venv/lib/python3.14/site-packages/django/views/decorators/csrf.py", line 65, in _view_wrapper
    return view_func(request, *args, **kwargs)
  File "/home/coderx64/hackathon/backend/venv/lib/python3.14/site-packages/rest_framework/viewsets.py", line 125, in view
    return self.dispatch(request, *args, **kwargs)
           ~~~~~~~~~~~~~^^^^^^^^^^^^^^^^^^^^^^^^^^
  File "/home/coderx64/hackathon/backend/venv/lib/python3.14/site-packages/rest_framework/views.py", line 515, in dispatch
    response = self.handle_exception(exc)
  File "/home/coderx64/hackathon/backend/venv/lib/python3.14/site-packages/rest_framework/views.py", line 475, in handle_exception
    self.raise_uncaught_exception(exc)
    ~~~~~~~~~~~~~~~~~~~~~~~~~~~~~^^^^^
  File "/home/coderx64/hackathon/backend/venv/lib/python3.14/site-packages/rest_framework/views.py", line 486, in raise_uncaught_exception
    raise exc
  File "/home/coderx64/hackathon/backend/venv/lib/python3.14/site-packages/rest_framework/views.py", line 503, in dispatch
    self.initial(request, *args, **kwargs)
    ~~~~~~~~~~~~^^^^^^^^^^^^^^^^^^^^^^^^^^
  File "/home/coderx64/hackathon/backend/venv/lib/python3.14/site-packages/rest_framework/views.py", line 420, in initial
    self.perform_authentication(request)
    ~~~~~~~~~~~~~~~~~~~~~~~~~~~^^^^^^^^^
  File "/home/coderx64/hackathon/backend/venv/lib/python3.14/site-packages/rest_framework/views.py", line 330, in perform_authentication
    request.user
  File "/home/coderx64/hackathon/backend/venv/lib/python3.14/site-packages/rest_framework/request.py", line 232, in user
    self._authenticate()
    ~~~~~~~~~~~~~~~~~~^^
  File "/home/coderx64/hackathon/backend/venv/lib/python3.14/site-packages/rest_framework/request.py", line 385, in _authenticate
    user_auth_tuple = authenticator.authenticate(self)
  File "/home/coderx64/hackathon/backend/venv/lib/python3.14/site-packages/rest_framework_simplejwt/authentication.py", line 51, in authenticate
    return self.get_user(validated_token), validated_token
           ~~~~~~~~~~~~~^^^^^^^^^^^^^^^^^
  File "/home/coderx64/hackathon/backend/venv/lib/python3.14/site-packages/rest_framework_simplejwt/authentication.py", line 132, in get_user
    user = self.user_model.objects.get(**{api_settings.USER_ID_FIELD: user_id})
  File "/home/coderx64/hackathon/backend/venv/lib/python3.14/site-packages/django/db/models/manager.py", line 87, in manager_method
    return getattr(self.get_queryset(), name)(*args, **kwargs)
           ~~~~~~~~~~~~~~~~~~~~~~~~~~~~~~~~~~^^^^^^^^^^^^^^^^^
  File "/home/coderx64/hackathon/backend/venv/lib/python3.14/site-packages/django/db/models/query.py", line 629, in get
    num = len(clone)
  File "/home/coderx64/hackathon/backend/venv/lib/python3.14/site-packages/django/db/models/query.py", line 366, in __len__
    self._fetch_all()
    ~~~~~~~~~~~~~~~^^
  File "/home/coderx64/hackathon/backend/venv/lib/python3.14/site-packages/django/db/models/query.py", line 1949, in _fetch_all
    self._result_cache = list(self._iterable_class(self))
                         ~~~~^^^^^^^^^^^^^^^^^^^^^^^^^^^^
  File "/home/coderx64/hackathon/backend/venv/lib/python3.14/site-packages/django/db/models/query.py", line 91, in __iter__
    results = compiler.execute_sql(
        chunked_fetch=self.chunked_fetch, chunk_size=self.chunk_size
    )
  File "/home/coderx64/hackathon/backend/venv/lib/python3.14/site-packages/django/db/models/sql/compiler.py", line 1623, in execute_sql
    cursor.execute(sql, params)
    ~~~~~~~~~~~~~~^^^^^^^^^^^^^
  File "/home/coderx64/hackathon/backend/venv/lib/python3.14/site-packages/django/db/backends/utils.py", line 79, in execute
    return self._execute_with_wrappers(
           ~~~~~~~~~~~~~~~~~~~~~~~~~~~^
        sql, params, many=False, executor=self._execute
        ^^^^^^^^^^^^^^^^^^^^^^^^^^^^^^^^^^^^^^^^^^^^^^^
    )
    ^
  File "/home/coderx64/hackathon/backend/venv/lib/python3.14/site-packages/django/db/backends/utils.py", line 92, in _execute_with_wrappers
    return executor(sql, params, many, context)
  File "/home/coderx64/hackathon/backend/venv/lib/python3.14/site-packages/django/db/backends/utils.py", line 100, in _execute
    with self.db.wrap_database_errors:
         ^^^^^^^^^^^^^^^^^^^^^^^^^^^^
  File "/home/coderx64/hackathon/backend/venv/lib/python3.14/site-packages/django/db/utils.py", line 91, in __exit__
    raise dj_exc_value.with_traceback(traceback) from exc_value
  File "/home/coderx64/hackathon/backend/venv/lib/python3.14/site-packages/django/db/backends/utils.py", line 105, in _execute
    return self.cursor.execute(sql, params)
           ~~~~~~~~~~~~~~~~~~~^^^^^^^^^^^^^
  File "/home/coderx64/hackathon/backend/venv/lib/python3.14/site-packages/django/db/backends/sqlite3/base.py", line 360, in execute
    return super().execute(query, params)
           ~~~~~~~~~~~~~~~^^^^^^^^^^^^^^^
django.db.utils.OperationalError: no such table: users
[ERROR] 2025-10-30 06:59:43 django.request 92119 140199602079552 Internal Server Error: /api/v1/job-orders/
Traceback (most recent call last):
  File "/home/coderx64/hackathon/backend/venv/lib/python3.14/site-packages/django/db/backends/utils.py", line 105, in _execute
    return self.cursor.execute(sql, params)
           ~~~~~~~~~~~~~~~~~~~^^^^^^^^^^^^^
  File "/home/coderx64/hackathon/backend/venv/lib/python3.14/site-packages/django/db/backends/sqlite3/base.py", line 360, in execute
    return super().execute(query, params)
           ~~~~~~~~~~~~~~~^^^^^^^^^^^^^^^
sqlite3.OperationalError: no such table: users

The above exception was the direct cause of the following exception:

Traceback (most recent call last):
  File "/home/coderx64/hackathon/backend/venv/lib/python3.14/site-packages/django/core/handlers/exception.py", line 55, in inner
    response = get_response(request)
  File "/home/coderx64/hackathon/backend/venv/lib/python3.14/site-packages/django/core/handlers/base.py", line 197, in _get_response
    response = wrapped_callback(request, *callback_args, **callback_kwargs)
  File "/home/coderx64/hackathon/backend/venv/lib/python3.14/site-packages/django/views/decorators/csrf.py", line 65, in _view_wrapper
    return view_func(request, *args, **kwargs)
  File "/home/coderx64/hackathon/backend/venv/lib/python3.14/site-packages/rest_framework/viewsets.py", line 125, in view
    return self.dispatch(request, *args, **kwargs)
           ~~~~~~~~~~~~~^^^^^^^^^^^^^^^^^^^^^^^^^^
  File "/home/coderx64/hackathon/backend/venv/lib/python3.14/site-packages/rest_framework/views.py", line 515, in dispatch
    response = self.handle_exception(exc)
  File "/home/coderx64/hackathon/backend/venv/lib/python3.14/site-packages/rest_framework/views.py", line 475, in handle_exception
    self.raise_uncaught_exception(exc)
    ~~~~~~~~~~~~~~~~~~~~~~~~~~~~~^^^^^
  File "/home/coderx64/hackathon/backend/venv/lib/python3.14/site-packages/rest_framework/views.py", line 486, in raise_uncaught_exception
    raise exc
  File "/home/coderx64/hackathon/backend/venv/lib/python3.14/site-packages/rest_framework/views.py", line 503, in dispatch
    self.initial(request, *args, **kwargs)
    ~~~~~~~~~~~~^^^^^^^^^^^^^^^^^^^^^^^^^^
  File "/home/coderx64/hackathon/backend/venv/lib/python3.14/site-packages/rest_framework/views.py", line 420, in initial
    self.perform_authentication(request)
    ~~~~~~~~~~~~~~~~~~~~~~~~~~~^^^^^^^^^
  File "/home/coderx64/hackathon/backend/venv/lib/python3.14/site-packages/rest_framework/views.py", line 330, in perform_authentication
    request.user
  File "/home/coderx64/hackathon/backend/venv/lib/python3.14/site-packages/rest_framework/request.py", line 232, in user
    self._authenticate()
    ~~~~~~~~~~~~~~~~~~^^
  File "/home/coderx64/hackathon/backend/venv/lib/python3.14/site-packages/rest_framework/request.py", line 385, in _authenticate
    user_auth_tuple = authenticator.authenticate(self)
  File "/home/coderx64/hackathon/backend/venv/lib/python3.14/site-packages/rest_framework_simplejwt/authentication.py", line 51, in authenticate
    return self.get_user(validated_token), validated_token
           ~~~~~~~~~~~~~^^^^^^^^^^^^^^^^^
  File "/home/coderx64/hackathon/backend/venv/lib/python3.14/site-packages/rest_framework_simplejwt/authentication.py", line 132, in get_user
    user = self.user_model.objects.get(**{api_settings.USER_ID_FIELD: user_id})
  File "/home/coderx64/hackathon/backend/venv/lib/python3.14/site-packages/django/db/models/manager.py", line 87, in manager_method
    return getattr(self.get_queryset(), name)(*args, **kwargs)
           ~~~~~~~~~~~~~~~~~~~~~~~~~~~~~~~~~~^^^^^^^^^^^^^^^^^
  File "/home/coderx64/hackathon/backend/venv/lib/python3.14/site-packages/django/db/models/query.py", line 629, in get
    num = len(clone)
  File "/home/coderx64/hackathon/backend/venv/lib/python3.14/site-packages/django/db/models/query.py", line 366, in __len__
    self._fetch_all()
    ~~~~~~~~~~~~~~~^^
  File "/home/coderx64/hackathon/backend/venv/lib/python3.14/site-packages/django/db/models/query.py", line 1949, in _fetch_all
    self._result_cache = list(self._iterable_class(self))
                         ~~~~^^^^^^^^^^^^^^^^^^^^^^^^^^^^
  File "/home/coderx64/hackathon/backend/venv/lib/python3.14/site-packages/django/db/models/query.py", line 91, in __iter__
    results = compiler.execute_sql(
        chunked_fetch=self.chunked_fetch, chunk_size=self.chunk_size
    )
  File "/home/coderx64/hackathon/backend/venv/lib/python3.14/site-packages/django/db/models/sql/compiler.py", line 1623, in execute_sql
    cursor.execute(sql, params)
    ~~~~~~~~~~~~~~^^^^^^^^^^^^^
  File "/home/coderx64/hackathon/backend/venv/lib/python3.14/site-packages/django/db/backends/utils.py", line 79, in execute
    return self._execute_with_wrappers(
           ~~~~~~~~~~~~~~~~~~~~~~~~~~~^
        sql, params, many=False, executor=self._execute
        ^^^^^^^^^^^^^^^^^^^^^^^^^^^^^^^^^^^^^^^^^^^^^^^
    )
    ^
  File "/home/coderx64/hackathon/backend/venv/lib/python3.14/site-packages/django/db/backends/utils.py", line 92, in _execute_with_wrappers
    return executor(sql, params, many, context)
  File "/home/coderx64/hackathon/backend/venv/lib/python3.14/site-packages/django/db/backends/utils.py", line 100, in _execute
    with self.db.wrap_database_errors:
         ^^^^^^^^^^^^^^^^^^^^^^^^^^^^
  File "/home/coderx64/hackathon/backend/venv/lib/python3.14/site-packages/django/db/utils.py", line 91, in __exit__
    raise dj_exc_value.with_traceback(traceback) from exc_value
  File "/home/coderx64/hackathon/backend/venv/lib/python3.14/site-packages/django/db/backends/utils.py", line 105, in _execute
    return self.cursor.execute(sql, params)
           ~~~~~~~~~~~~~~~~~~~^^^^^^^^^^^^^
  File "/home/coderx64/hackathon/backend/venv/lib/python3.14/site-packages/django/db/backends/sqlite3/base.py", line 360, in execute
    return super().execute(query, params)
           ~~~~~~~~~~~~~~~^^^^^^^^^^^^^^^
django.db.utils.OperationalError: no such table: users
[ERROR] 2025-10-30 06:59:44 django.request 92122 140199602079552 Internal Server Error: /api/v1/auth/logout/
Traceback (most recent call last):
  File "/home/coderx64/hackathon/backend/venv/lib/python3.14/site-packages/django/db/backends/utils.py", line 105, in _execute
    return self.cursor.execute(sql, params)
           ~~~~~~~~~~~~~~~~~~~^^^^^^^^^^^^^
  File "/home/coderx64/hackathon/backend/venv/lib/python3.14/site-packages/django/db/backends/sqlite3/base.py", line 360, in execute
    return super().execute(query, params)
           ~~~~~~~~~~~~~~~^^^^^^^^^^^^^^^
sqlite3.OperationalError: no such table: token_blacklist_blacklistedtoken

The above exception was the direct cause of the following exception:

Traceback (most recent call last):
  File "/home/coderx64/hackathon/backend/venv/lib/python3.14/site-packages/django/core/handlers/exception.py", line 55, in inner
    response = get_response(request)
  File "/home/coderx64/hackathon/backend/venv/lib/python3.14/site-packages/django/core/handlers/base.py", line 197, in _get_response
    response = wrapped_callback(request, *callback_args, **callback_kwargs)
  File "/home/coderx64/hackathon/backend/venv/lib/python3.14/site-packages/django/views/decorators/csrf.py", line 65, in _view_wrapper
    return view_func(request, *args, **kwargs)
  File "/home/coderx64/hackathon/backend/venv/lib/python3.14/site-packages/django/views/generic/base.py", line 105, in view
    return self.dispatch(request, *args, **kwargs)
           ~~~~~~~~~~~~~^^^^^^^^^^^^^^^^^^^^^^^^^^
  File "/home/coderx64/hackathon/backend/venv/lib/python3.14/site-packages/rest_framework/views.py", line 515, in dispatch
    response = self.handle_exception(exc)
  File "/home/coderx64/hackathon/backend/venv/lib/python3.14/site-packages/rest_framework/views.py", line 475, in handle_exception
    self.raise_uncaught_exception(exc)
    ~~~~~~~~~~~~~~~~~~~~~~~~~~~~~^^^^^
  File "/home/coderx64/hackathon/backend/venv/lib/python3.14/site-packages/rest_framework/views.py", line 486, in raise_uncaught_exception
    raise exc
  File "/home/coderx64/hackathon/backend/venv/lib/python3.14/site-packages/rest_framework/views.py", line 512, in dispatch
    response = handler(request, *args, **kwargs)
  File "/home/coderx64/hackathon/backend/venv/lib/python3.14/site-packages/rest_framework_simplejwt/views.py", line 46, in post
    serializer.is_valid(raise_exception=True)
    ~~~~~~~~~~~~~~~~~~~^^^^^^^^^^^^^^^^^^^^^^
  File "/home/coderx64/hackathon/backend/venv/lib/python3.14/site-packages/rest_framework/serializers.py", line 225, in is_valid
    self._validated_data = self.run_validation(self.initial_data)
                           ~~~~~~~~~~~~~~~~~~~^^^^^^^^^^^^^^^^^^^
  File "/home/coderx64/hackathon/backend/venv/lib/python3.14/site-packages/rest_framework/serializers.py", line 447, in run_validation
    value = self.validate(value)
  File "/home/coderx64/hackathon/backend/venv/lib/python3.14/site-packages/rest_framework_simplejwt/serializers.py", line 188, in validate
    refresh = self.token_class(attrs["refresh"])
  File "/home/coderx64/hackathon/backend/venv/lib/python3.14/site-packages/rest_framework_simplejwt/tokens.py", line 72, in __init__
    self.verify()
    ~~~~~~~~~~~^^
  File "/home/coderx64/hackathon/backend/venv/lib/python3.14/site-packages/rest_framework_simplejwt/tokens.py", line 268, in verify
    self.check_blacklist()
    ~~~~~~~~~~~~~~~~~~~~^^
  File "/home/coderx64/hackathon/backend/venv/lib/python3.14/site-packages/rest_framework_simplejwt/tokens.py", line 279, in check_blacklist
    if BlacklistedToken.objects.filter(token__jti=jti).exists():
       ~~~~~~~~~~~~~~~~~~~~~~~~~~~~~~~~~~~~~~~~~~~~~~~~~~~~~~^^
  File "/home/coderx64/hackathon/backend/venv/lib/python3.14/site-packages/django/db/models/query.py", line 1296, in exists
    return self.query.has_results(using=self.db)
           ~~~~~~~~~~~~~~~~~~~~~~^^^^^^^^^^^^^^^
  File "/home/coderx64/hackathon/backend/venv/lib/python3.14/site-packages/django/db/models/sql/query.py", line 674, in has_results
    return compiler.has_results()
           ~~~~~~~~~~~~~~~~~~~~^^
  File "/home/coderx64/hackathon/backend/venv/lib/python3.14/site-packages/django/db/models/sql/compiler.py", line 1591, in has_results
    return bool(self.execute_sql(SINGLE))
                ~~~~~~~~~~~~~~~~^^^^^^^^
  File "/home/coderx64/hackathon/backend/venv/lib/python3.14/site-packages/django/db/models/sql/compiler.py", line 1623, in execute_sql
    cursor.execute(sql, params)
    ~~~~~~~~~~~~~~^^^^^^^^^^^^^
  File "/home/coderx64/hackathon/backend/venv/lib/python3.14/site-packages/django/db/backends/utils.py", line 79, in execute
    return self._execute_with_wrappers(
           ~~~~~~~~~~~~~~~~~~~~~~~~~~~^
        sql, params, many=False, executor=self._execute
        ^^^^^^^^^^^^^^^^^^^^^^^^^^^^^^^^^^^^^^^^^^^^^^^
    )
    ^
  File "/home/coderx64/hackathon/backend/venv/lib/python3.14/site-packages/django/db/backends/utils.py", line 92, in _execute_with_wrappers
    return executor(sql, params, many, context)
  File "/home/coderx64/hackathon/backend/venv/lib/python3.14/site-packages/django/db/backends/utils.py", line 100, in _execute
    with self.db.wrap_database_errors:
         ^^^^^^^^^^^^^^^^^^^^^^^^^^^^
  File "/home/coderx64/hackathon/backend/venv/lib/python3.14/site-packages/django/db/utils.py", line 91, in __exit__
    raise dj_exc_value.with_traceback(traceback) from exc_value
  File "/home/coderx64/hackathon/backend/venv/lib/python3.14/site-packages/django/db/backends/utils.py", line 105, in _execute
    return self.cursor.execute(sql, params)
           ~~~~~~~~~~~~~~~~~~~^^^^^^^^^^^^^
  File "/home/coderx64/hackathon/backend/venv/lib/python3.14/site-packages/django/db/backends/sqlite3/base.py", line 360, in execute
    return super().execute(query, params)
           ~~~~~~~~~~~~~~~^^^^^^^^^^^^^^^
django.db.utils.OperationalError: no such table: token_blacklist_blacklistedtoken
[ERROR] 2025-10-30 06:59:46 django.request 92122 140199602079552 Internal Server Error: /api/v1/auth/login/
Traceback (most recent call last):
  File "/home/coderx64/hackathon/backend/venv/lib/python3.14/site-packages/django/db/backends/utils.py", line 105, in _execute
    return self.cursor.execute(sql, params)
           ~~~~~~~~~~~~~~~~~~~^^^^^^^^^^^^^
  File "/home/coderx64/hackathon/backend/venv/lib/python3.14/site-packages/django/db/backends/sqlite3/base.py", line 360, in execute
    return super().execute(query, params)
           ~~~~~~~~~~~~~~~^^^^^^^^^^^^^^^
sqlite3.OperationalError: no such table: users

The above exception was the direct cause of the following exception:

Traceback (most recent call last):
  File "/home/coderx64/hackathon/backend/venv/lib/python3.14/site-packages/django/core/handlers/exception.py", line 55, in inner
    response = get_response(request)
  File "/home/coderx64/hackathon/backend/venv/lib/python3.14/site-packages/django/core/handlers/base.py", line 197, in _get_response
    response = wrapped_callback(request, *callback_args, **callback_kwargs)
  File "/home/coderx64/hackathon/backend/venv/lib/python3.14/site-packages/django/views/decorators/csrf.py", line 65, in _view_wrapper
    return view_func(request, *args, **kwargs)
  File "/home/coderx64/hackathon/backend/venv/lib/python3.14/site-packages/django/views/generic/base.py", line 105, in view
    return self.dispatch(request, *args, **kwargs)
           ~~~~~~~~~~~~~^^^^^^^^^^^^^^^^^^^^^^^^^^
  File "/home/coderx64/hackathon/backend/venv/lib/python3.14/site-packages/rest_framework/views.py", line 515, in dispatch
    response = self.handle_exception(exc)
  File "/home/coderx64/hackathon/backend/venv/lib/python3.14/site-packages/rest_framework/views.py", line 475, in handle_exception
    self.raise_uncaught_exception(exc)
    ~~~~~~~~~~~~~~~~~~~~~~~~~~~~~^^^^^
  File "/home/coderx64/hackathon/backend/venv/lib/python3.14/site-packages/rest_framework/views.py", line 486, in raise_uncaught_exception
    raise exc
  File "/home/coderx64/hackathon/backend/venv/lib/python3.14/site-packages/rest_framework/views.py", line 512, in dispatch
    response = handler(request, *args, **kwargs)
  File "/home/coderx64/hackathon/backend/venv/lib/python3.14/site-packages/rest_framework_simplejwt/views.py", line 46, in post
    serializer.is_valid(raise_exception=True)
    ~~~~~~~~~~~~~~~~~~~^^^^^^^^^^^^^^^^^^^^^^
  File "/home/coderx64/hackathon/backend/venv/lib/python3.14/site-packages/rest_framework/serializers.py", line 225, in is_valid
    self._validated_data = self.run_validation(self.initial_data)
                           ~~~~~~~~~~~~~~~~~~~^^^^^^^^^^^^^^^^^^^
  File "/home/coderx64/hackathon/backend/venv/lib/python3.14/site-packages/rest_framework/serializers.py", line 447, in run_validation
    value = self.validate(value)
  File "/home/coderx64/hackathon/backend/core/serializers_auth.py", line 11, in validate
    data = super().validate(attrs)
  File "/home/coderx64/hackathon/backend/venv/lib/python3.14/site-packages/rest_framework_simplejwt/serializers.py", line 73, in validate
    data = super().validate(attrs)
  File "/home/coderx64/hackathon/backend/venv/lib/python3.14/site-packages/rest_framework_simplejwt/serializers.py", line 54, in validate
    self.user = authenticate(**authenticate_kwargs)
                ~~~~~~~~~~~~^^^^^^^^^^^^^^^^^^^^^^^
  File "/home/coderx64/hackathon/backend/venv/lib/python3.14/site-packages/django/views/decorators/debug.py", line 75, in sensitive_variables_wrapper
    return func(*func_args, **func_kwargs)
  File "/home/coderx64/hackathon/backend/venv/lib/python3.14/site-packages/django/contrib/auth/__init__.py", line 114, in authenticate
    user = backend.authenticate(request, **credentials)
  File "/home/coderx64/hackathon/backend/venv/lib/python3.14/site-packages/django/contrib/auth/backends.py", line 65, in authenticate
    user = UserModel._default_manager.get_by_natural_key(username)
  File "/home/coderx64/hackathon/backend/venv/lib/python3.14/site-packages/django/contrib/auth/base_user.py", line 37, in get_by_natural_key
    return self.get(**{self.model.USERNAME_FIELD: username})
           ~~~~~~~~^^^^^^^^^^^^^^^^^^^^^^^^^^^^^^^^^^^^^^^^^
  File "/home/coderx64/hackathon/backend/venv/lib/python3.14/site-packages/django/db/models/manager.py", line 87, in manager_method
    return getattr(self.get_queryset(), name)(*args, **kwargs)
           ~~~~~~~~~~~~~~~~~~~~~~~~~~~~~~~~~~^^^^^^^^^^^^^^^^^
  File "/home/coderx64/hackathon/backend/venv/lib/python3.14/site-packages/django/db/models/query.py", line 629, in get
    num = len(clone)
  File "/home/coderx64/hackathon/backend/venv/lib/python3.14/site-packages/django/db/models/query.py", line 366, in __len__
    self._fetch_all()
    ~~~~~~~~~~~~~~~^^
  File "/home/coderx64/hackathon/backend/venv/lib/python3.14/site-packages/django/db/models/query.py", line 1949, in _fetch_all
    self._result_cache = list(self._iterable_class(self))
                         ~~~~^^^^^^^^^^^^^^^^^^^^^^^^^^^^
  File "/home/coderx64/hackathon/backend/venv/lib/python3.14/site-packages/django/db/models/query.py", line 91, in __iter__
    results = compiler.execute_sql(
        chunked_fetch=self.chunked_fetch, chunk_size=self.chunk_size
    )
  File "/home/coderx64/hackathon/backend/venv/lib/python3.14/site-packages/django/db/models/sql/compiler.py", line 1623, in execute_sql
    cursor.execute(sql, params)
    ~~~~~~~~~~~~~~^^^^^^^^^^^^^
  File "/home/coderx64/hackathon/backend/venv/lib/python3.14/site-packages/django/db/backends/utils.py", line 79, in execute
    return self._execute_with_wrappers(
           ~~~~~~~~~~~~~~~~~~~~~~~~~~~^
        sql, params, many=False, executor=self._execute
        ^^^^^^^^^^^^^^^^^^^^^^^^^^^^^^^^^^^^^^^^^^^^^^^
    )
    ^
  File "/home/coderx64/hackathon/backend/venv/lib/python3.14/site-packages/django/db/backends/utils.py", line 92, in _execute_with_wrappers
    return executor(sql, params, many, context)
  File "/home/coderx64/hackathon/backend/venv/lib/python3.14/site-packages/django/db/backends/utils.py", line 100, in _execute
    with self.db.wrap_database_errors:
         ^^^^^^^^^^^^^^^^^^^^^^^^^^^^
  File "/home/coderx64/hackathon/backend/venv/lib/python3.14/site-packages/django/db/utils.py", line 91, in __exit__
    raise dj_exc_value.with_traceback(traceback) from exc_value
  File "/home/coderx64/hackathon/backend/venv/lib/python3.14/site-packages/django/db/backends/utils.py", line 105, in _execute
    return self.cursor.execute(sql, params)
           ~~~~~~~~~~~~~~~~~~~^^^^^^^^^^^^^
  File "/home/coderx64/hackathon/backend/venv/lib/python3.14/site-packages/django/db/backends/sqlite3/base.py", line 360, in execute
    return super().execute(query, params)
           ~~~~~~~~~~~~~~~^^^^^^^^^^^^^^^
django.db.utils.OperationalError: no such table: users
[WARNING] 2025-10-30 07:38:18 django.request 96177 140556578821952 Unauthorized: /api/v1/auth/login/
[WARNING] 2025-10-30 07:38:40 django.request 96193 140556578821952 Unauthorized: /api/v1/auth/login/
[WARNING] 2025-10-30 07:40:43 django.request 96193 140556578821952 Unauthorized: /api/v1/metrics/job-order/6/
[WARNING] 2025-10-30 07:40:43 django.request 96177 140556578821952 Unauthorized: /api/v1/metrics/job-order/4/
[WARNING] 2025-10-30 07:40:43 django.request 96192 140556578821952 Unauthorized: /api/v1/metrics/job-order/5/
[WARNING] 2025-10-30 07:40:43 django.request 96189 140556578821952 Unauthorized: /api/v1/metrics/job-order/3/
[WARNING] 2025-10-30 07:40:43 django.request 96177 140556578821952 Unauthorized: /api/v1/metrics/job-order/2/
[WARNING] 2025-10-30 07:40:43 django.request 96192 140556578821952 Unauthorized: /api/v1/metrics/job-order/1/
[WARNING] 2025-10-30 07:40:43 django.request 96177 140556578821952 Unauthorized: /api/v1/metrics/technician/5/
[WARNING] 2025-10-30 07:40:43 django.request 96193 140556578821952 Unauthorized: /api/v1/inspections/
[WARNING] 2025-10-30 07:40:43 django.request 96189 140556578821952 Unauthorized: /api/v1/metrics/technician/4/
[WARNING] 2025-10-30 07:40:43 django.request 96192 140556578821952 Unauthorized: /api/v1/metrics/technician/6/
[INFO] 2025-10-30 12:18:55 django.utils.autoreload 45385 127811443113984 Watching for file changes with StatReloader
[INFO] 2025-10-30 12:19:37 django.server 45385 127810363455040 "OPTIONS /api/v1/auth/login/ HTTP/1.1" 200 0
[WARNING] 2025-10-30 12:19:37 django.request 45385 127810363455040 Unauthorized: /api/v1/auth/login/
[WARNING] 2025-10-30 12:19:37 django.server 45385 127810363455040 "POST /api/v1/auth/login/ HTTP/1.1" 401 63
[WARNING] 2025-10-30 12:20:10 django.request 45385 127810363455040 Unauthorized: /api/v1/auth/login/
[WARNING] 2025-10-30 12:20:10 django.server 45385 127810363455040 "POST /api/v1/auth/login/ HTTP/1.1" 401 63
[WARNING] 2025-10-30 12:20:47 django.request 45385 127810363455040 Unauthorized: /api/v1/auth/login/
[WARNING] 2025-10-30 12:20:47 django.server 45385 127810363455040 "POST /api/v1/auth/login/ HTTP/1.1" 401 63
